<robot name="mobile_robot">

  <link name="base_link">
    <visual>
      <geometry>
        <box size="0.41 0.22 0.10"/>
      </geometry>
      <origin rpy="0 0 0" xyz="0.115 0 0.06"/>
      <material name="white">
        <color rgba="1 1 1 1"/>
      </material>
    </visual>
  </link>
  
  <link name="rwheel">
    <visual>
      <geometry>
        <cylinder length="0.02" radius="0.034"/>
      </geometry>
      <origin rpy="0 0 0" xyz="0 0 0"/>
      <material name="black">
        <color rgba="0 0 0 1"/>
      </material>
    </visual>
  </link>
  
  <joint name="base_to_rwheel" type="continuous">
    <parent link="base_link"/>
    <child link="rwheel"/>
    <origin xyz="0 -0.12 0.034" rpy="1.5708 0 0"/>
  </joint>
  
  <link name="lwheel">
    <visual>
      <geometry>
        <cylinder length="0.02" radius="0.034"/>
      </geometry>
      <origin rpy="0 0 0" xyz="0 0 0"/>
      <material name="black">
        <color rgba="0 0 0 1"/>
      </material>
    </visual>
  </link>
  
  <joint name="base_to_lwheel" type="continuous">
    <parent link="base_link"/>
    <child link="lwheel"/>
    <origin xyz="0 0.12 0.034" rpy="-1.5708 0 0"/>
  </joint>
  
  <link name="fwheel_attach">
    <visual>
      <geometry>
        <cylinder length="0.060" radius="0.023"/>
      </geometry>
      <origin xyz="0 0 0" rpy="0 0 0"/>  
      <material name="white">
        <color rgba="1 1 1 1"/>
      </material>
    </visual>
  </link>
  
  <joint name="base_to_fattach" type="continuous">
    <parent link="base_link"/>
    <child link="fwheel_attach"/>
    <origin rpy="0 0 0" xyz="0.24 0 0.045"/>
    
  </joint>
  
  <link name="fwheel">
    <visual>
      <geometry>
        <cylinder length="0.01" radius="0.020"/>
      </geometry>
      <origin rpy="1.578 0 0" xyz="0 0 0"/>
      <material name="black">
        <color rgba="0 0 0 1"/>
      </material>
    </visual>
  </link>
  
  <joint name="base_to_fwheel" type="continuous">
    <parent link="base_link"/>
    <child link="fwheel"/>
    <origin xyz="0.24 0 0.02" rpy="0 0 0"/>
  </joint>
  
  <link name="scanner">
    <visual>
      <geometry>
        <cylinder radius="0.02" length="0.065"/>
      </geometry>
      <origin rpy="0 0 0" xyz="0 0 0"/>
      <material name="black">
        <color rgba="0 0 0 1"/>
      </material>
    </visual>
  </link>
  
  <joint name="base_to_scanner" type="revolute">
    <limit lower="0" upper="1.57" effort="0.1" velocity="0.1"/>
    <parent link="base_link"/>
    <child link="scanner"/>
    <origin xyz="0.26 0 0.10" rpy="0 0 -1.57"/>
    
  </joint>
  

</robot>
